<sdf version='1.7'>
  <world name='default'>
    <light name='sun' type='directional'>
      <cast_shadows>1</cast_shadows>
      <pose>0 0 10 0 -0 0</pose>
      <diffuse>0.8 0.8 0.8 1</diffuse>
      <specular>0.2 0.2 0.2 1</specular>
      <attenuation>
        <range>1000</range>
        <constant>0.9</constant>
        <linear>0.01</linear>
        <quadratic>0.001</quadratic>
      </attenuation>
      <direction>-0.5 0.1 -0.9</direction>
      <spot>
        <inner_angle>0</inner_angle>
        <outer_angle>0</outer_angle>
        <falloff>0</falloff>
      </spot>
    </light>
    <model name='ground_plane'>
      <static>1</static>
      <link name='link'>
        <collision name='collision'>
          <geometry>
            <plane>
              <normal>0 0 1</normal>
              <size>100 100</size>
            </plane>
          </geometry>
          <surface>
            <friction>
              <ode>
                <mu>100</mu>
                <mu2>50</mu2>
              </ode>
              <torsional>
                <ode/>
              </torsional>
            </friction>
            <contact>
              <ode/>
            </contact>
            <bounce/>
          </surface>
          <max_contacts>10</max_contacts>
        </collision>
        <visual name='visual'>
          <cast_shadows>0</cast_shadows>
          <geometry>
            <plane>
              <normal>0 0 1</normal>
              <size>100 100</size>
            </plane>
          </geometry>
          <material>
            <script>
              <uri>file://media/materials/scripts/gazebo.material</uri>
              <name>Gazebo/Grey</name>
            </script>
          </material>
        </visual>
        <self_collide>0</self_collide>
        <enable_wind>0</enable_wind>
        <kinematic>0</kinematic>
      </link>
    </model>
    <gravity>0 0 -9.8</gravity>
    <magnetic_field>6e-06 2.3e-05 -4.2e-05</magnetic_field>
    <atmosphere type='adiabatic'/>
    <physics type='ode'>
      <max_step_size>0.001</max_step_size>
      <real_time_factor>1</real_time_factor>
      <real_time_update_rate>1000</real_time_update_rate>
    </physics>
    <scene>
      <ambient>0.4 0.4 0.4 1</ambient>
      <background>0.7 0.7 0.7 1</background>
      <shadows>1</shadows>
    </scene>
    <wind/>
    <spherical_coordinates>
      <surface_model>EARTH_WGS84</surface_model>
      <latitude_deg>0</latitude_deg>
      <longitude_deg>0</longitude_deg>
      <elevation>0</elevation>
      <heading_deg>0</heading_deg>
    </spherical_coordinates>
    <model name='me439_robot'>
      <static>0</static>
      <link name='chassis'>
        <pose>0 0 0.1 0 -0 0</pose>
        <inertial>
          <mass>1</mass>
          <inertia>
            <ixx>0.083</ixx>
            <ixy>0</ixy>
            <ixz>0</ixz>
            <iyy>0.083</iyy>
            <iyz>0</iyz>
            <izz>0.083</izz>
          </inertia>
          <pose>0 0 0 0 -0 0</pose>
        </inertial>
        <collision name='collision'>
          <geometry>
            <box>
              <size>0.8 0.4 0.1</size>
            </box>
          </geometry>
          <max_contacts>10</max_contacts>
          <surface>
            <contact>
              <ode/>
            </contact>
            <bounce/>
            <friction>
              <torsional>
                <ode/>
              </torsional>
              <ode/>
            </friction>
          </surface>
        </collision>
        <visual name='visual'>
          <geometry>
            <box>
              <size>0.8 0.4 0.1</size>
            </box>
          </geometry>
        </visual>
        <collision name='caster_collision'>
          <pose>-0.3 0 -0.06 0 -0 0</pose>
          <geometry>
            <sphere>
              <radius>0.06</radius>
            </sphere>
          </geometry>
          <surface>
            <friction>
              <ode>
                <mu>0</mu>
                <mu2>0</mu2>
                <slip1>1</slip1>
                <slip2>1</slip2>
              </ode>
              <torsional>
                <ode/>
              </torsional>
            </friction>
            <contact>
              <ode/>
            </contact>
            <bounce/>
          </surface>
          <max_contacts>10</max_contacts>
        </collision>
        <visual name='caster_visual'>
          <pose>-0.3 0 -0.06 0 -0 0</pose>
          <geometry>
            <sphere>
              <radius>0.06</radius>
            </sphere>
          </geometry>
        </visual>
        <self_collide>0</self_collide>
        <enable_wind>0</enable_wind>
        <kinematic>0</kinematic>
      </link>
      <link name='vertical_link'>
        <pose relative_to='chassis'>-0.1 0 0.3 0 -0 0</pose>
        <collision name='vertical_collision'>
          <geometry>
            <box>
              <size>0.1 0.6 0.6</size>
            </box>
          </geometry>
          <max_contacts>10</max_contacts>
          <surface>
            <contact>
              <ode/>
            </contact>
            <bounce/>
            <friction>
              <torsional>
                <ode/>
              </torsional>
              <ode/>
            </friction>
          </surface>
          <inertial>
            <mass>1.0</mass>
            <inertia>
              <ixx>0.083</ixx>
              <ixy>0.0</ixy>
              <ixz>0.0</ixz>
              <iyy>0.083</iyy>
              <iyz>0.0</iyz>
              <izz>0.083</izz>
            </inertia>
          </inertial>
        </collision>
        <visual name='vertical_visual'>
          <geometry>
            <box>
              <size>0.1 0.6 0.6</size>
            </box>
          </geometry>
        </visual>
        <self_collide>0</self_collide>
        <inertial>
          <pose>0 0 0 0 -0 0</pose>
          <inertia>
            <ixx>1</ixx>
            <ixy>0</ixy>
            <ixz>0</ixz>
            <iyy>1</iyy>
            <iyz>0</iyz>
            <izz>1</izz>
          </inertia>
          <mass>1</mass>
        </inertial>
        <enable_wind>0</enable_wind>
        <kinematic>0</kinematic>
      </link>
      <link name='aruco_marker_link'>
        <pose relative_to='vertical_link'>0.051 -0.12 0 -9.3e-05 1.57079 3.14159</pose>
        <visual name='visual'>
          <geometry>
            <box>
              <size>0.296 0.296 1e-05</size>
            </box>
          </geometry>
          <material>
            <script>
              <uri>model://moving_platform_with_aruco/materials/scripts</uri>
              <uri>model://moving_platform_with_aruco/materials/textures</uri>
              <name>ArucoVisualMarker1/Marker</name>
            </script>
            <ambient>1 1 1 1</ambient>
            <diffuse>1 1 1 1</diffuse>
            <specular>0 0 0 1</specular>
            <emissive>1 1 1 0</emissive>
            <shader type='vertex'>
              <normal_map>__default__</normal_map>
            </shader>
          </material>
          <cast_shadows>1</cast_shadows>
          <transparency>0</transparency>
        </visual>
        <self_collide>0</self_collide>
        <inertial>
          <pose>0 0 0 0 -0 0</pose>
          <inertia>
            <ixx>1</ixx>
            <ixy>0</ixy>
            <ixz>0</ixz>
            <iyy>1</iyy>
            <iyz>0</iyz>
            <izz>1</izz>
          </inertia>
          <mass>1</mass>
        </inertial>
        <enable_wind>0</enable_wind>
        <kinematic>0</kinematic>
      </link>
      <link name='aruco_marker_link_2'>
        <pose relative_to='vertical_link'>0.051 0.11 -0.05 -9.3e-05 1.57079 3.14159</pose>
        <visual name='visual'>
          <geometry>
            <box>
              <size>0.1355 0.1355 1e-05</size>
            </box>
          </geometry>
          <material>
            <script>
              <uri>model://marker_0/materials/scripts</uri>
              <uri>model://marker_0/materials/textures</uri>
              <name>ArucoVisualMarker0/Marker</name>
            </script>
            <ambient>1 1 1 1</ambient>
            <diffuse>1 1 1 1</diffuse>
            <specular>0 0 0 1</specular>
            <emissive>1 1 1 0</emissive>
            <shader type='vertex'>
              <normal_map>__default__</normal_map>
            </shader>
          </material>
          <cast_shadows>1</cast_shadows>
          <transparency>0</transparency>
        </visual>
        <self_collide>0</self_collide>
        <inertial>
          <pose>0 0 0 0 -0 0</pose>
          <inertia>
            <ixx>1</ixx>
            <ixy>0</ixy>
            <ixz>0</ixz>
            <iyy>1</iyy>
            <iyz>0</iyz>
            <izz>1</izz>
          </inertia>
          <mass>1</mass>
        </inertial>
        <enable_wind>0</enable_wind>
        <kinematic>0</kinematic>
      </link>
      <link name='left_wheel'>
        <pose>0.2 0.23 0.1 -0 1.5707 1.5707</pose>
        <collision name='collision'>
          <geometry>
            <cylinder>
              <radius>0.15</radius>
              <length>0.06</length>
            </cylinder>
          </geometry>
          <max_contacts>10</max_contacts>
          <surface>
            <contact>
              <ode/>
            </contact>
            <bounce/>
            <friction>
              <torsional>
                <ode/>
              </torsional>
              <ode/>
            </friction>
          </surface>
        </collision>
        <visual name='visual'>
          <geometry>
            <cylinder>
              <radius>0.15</radius>
              <length>0.06</length>
            </cylinder>
          </geometry>
        </visual>
        <self_collide>0</self_collide>
        <inertial>
          <pose>0 0 0 0 -0 0</pose>
          <inertia>
            <ixx>1</ixx>
            <ixy>0</ixy>
            <ixz>0</ixz>
            <iyy>1</iyy>
            <iyz>0</iyz>
            <izz>1</izz>
          </inertia>
          <mass>1</mass>
        </inertial>
        <enable_wind>0</enable_wind>
        <kinematic>0</kinematic>
      </link>
      <link name='right_wheel'>
        <pose>0.2 -0.23 0.1 -0 1.5707 1.5707</pose>
        <collision name='collision'>
          <geometry>
            <cylinder>
              <radius>0.15</radius>
              <length>0.06</length>
            </cylinder>
          </geometry>
          <max_contacts>10</max_contacts>
          <surface>
            <contact>
              <ode/>
            </contact>
            <bounce/>
            <friction>
              <torsional>
                <ode/>
              </torsional>
              <ode/>
            </friction>
          </surface>
        </collision>
        <visual name='visual'>
          <geometry>
            <cylinder>
              <radius>0.15</radius>
              <length>0.06</length>
            </cylinder>
          </geometry>
        </visual>
        <self_collide>0</self_collide>
        <inertial>
          <pose>0 0 0 0 -0 0</pose>
          <inertia>
            <ixx>1</ixx>
            <ixy>0</ixy>
            <ixz>0</ixz>
            <iyy>1</iyy>
            <iyz>0</iyz>
            <izz>1</izz>
          </inertia>
          <mass>1</mass>
        </inertial>
        <enable_wind>0</enable_wind>
        <kinematic>0</kinematic>
      </link>
      <joint name='vertical_platform' type='fixed'>
        <pose>0 0 0 0 -0 0</pose>
        <child>vertical_link</child>
        <parent>chassis</parent>
        <axis>
          <xyz>0 0 0</xyz>
          <limit>
            <lower>-1e+16</lower>
            <upper>1e+16</upper>
          </limit>
        </axis>
      </joint>
      <joint name='aruco_1_fix' type='fixed'>
        <pose>0 0 0 0 -0 0</pose>
        <child>aruco_marker_link</child>
        <parent>vertical_link</parent>
        <axis>
          <xyz>0 0 0</xyz>
          <limit>
            <lower>-1e+16</lower>
            <upper>1e+16</upper>
          </limit>
        </axis>
      </joint>
      <joint name='aruco_2_fix' type='fixed'>
        <pose>0 0 0 0 -0 0</pose>
        <child>aruco_marker_link_2</child>
        <parent>vertical_link</parent>
        <axis>
          <xyz>0 0 0</xyz>
          <limit>
            <lower>-1e+16</lower>
            <upper>1e+16</upper>
          </limit>
        </axis>
      </joint>
      <joint name='left_wheel_hinge' type='revolute'>
        <pose>0 0 0 0 -0 0</pose>
        <child>left_wheel</child>
        <parent>chassis</parent>
        <axis>
          <xyz>0 0 1</xyz>
          <limit>
            <lower>-1e+16</lower>
            <upper>1e+16</upper>
          </limit>
          <dynamics>
            <spring_reference>0</spring_reference>
            <spring_stiffness>0</spring_stiffness>
          </dynamics>
        </axis>
      </joint>
      <joint name='right_wheel_hinge' type='revolute'>
        <pose>0 0 0 0 -0 0</pose>
        <child>right_wheel</child>
        <parent>chassis</parent>
        <axis>
          <xyz>0 0 1</xyz>
          <limit>
            <lower>-1e+16</lower>
            <upper>1e+16</upper>
          </limit>
          <dynamics>
            <spring_reference>0</spring_reference>
            <spring_stiffness>0</spring_stiffness>
          </dynamics>
        </axis>
      </joint>
      <plugin name='model_diff_drive_plugin' filename='libgazebo_ros_diff_drive.so'>
        <ros>
          <namespace>/platform_robot</namespace>
          <remapping>cmd_vel:=cmd_platform_robot</remapping>
          <remapping>odom:=odom_platform_robot</remapping>
        </ros>
        <wheel_separation>0.46</wheel_separation>
        <wheel_diameter>0.3</wheel_diameter>
        <left_joint>left_wheel_hinge</left_joint>
        <right_joint>right_wheel_hinge</right_joint>
        <publish_odom>1</publish_odom>
      </plugin>
      <pose>1.68945 2.19698 0 0 -0 0</pose>
    </model>
    <state world_name='default'>
      <sim_time>602 142000000</sim_time>
      <real_time>605 792707437</real_time>
      <wall_time>1648426077 334285038</wall_time>
      <iterations>602142</iterations>
      <model name='ground_plane'>
        <pose>0 0 0 0 -0 0</pose>
        <scale>1 1 1</scale>
        <link name='link'>
          <pose>0 0 0 0 -0 0</pose>
          <velocity>0 0 0 0 -0 0</velocity>
          <acceleration>0 0 0 0 -0 0</acceleration>
          <wrench>0 0 0 0 -0 0</wrench>
        </link>
      </model>
      <model name='me439_robot'>
        <pose>1.17442 1.58147 0.038139 -4e-06 -0.060258 -2.22632</pose>
        <scale>1 1 1</scale>
        <link name='aruco_marker_link'>
          <pose>1.12379 1.71249 0.434463 3.14144 1.51055 -2.22638</pose>
          <velocity>-0.000946 -7.8e-05 -0.000774 0.001555 -0.002982 0.000436</velocity>
          <acceleration>-0.249748 -0.314243 -0.855418 -0.882329 -1.38514 -3.12534</acceleration>
          <wrench>-0.249748 -0.314243 -0.855418 0 -0 0</wrench>
        </link>
        <link name='aruco_marker_link_2'>
          <pose>1.30428 1.5699 0.384553 3.14144 1.51055 -2.22637</pose>
          <velocity>-0.000732 7.5e-05 -0.000462 0.001565 -0.002973 0.000436</velocity>
          <acceleration>-0.165705 -0.208545 -0.864058 -0.855216 -1.36274 -3.12628</acceleration>
          <wrench>-0.165705 -0.208545 -0.864058 0 -0 0</wrench>
        </link>
        <link name='chassis'>
          <pose>1.17809 1.58625 0.137957 -4e-06 -0.060258 -2.22632</pose>
          <velocity>-2e-06 0.000401 -0.00081 0.001474 -0.003055 0.00044</velocity>
          <acceleration>0.261242 0.341544 -0.81239 -0.4658 -1.07561 -3.11666</acceleration>
          <wrench>0.261242 0.341544 -0.81239 0 -0 0</wrench>
        </link>
        <link name='left_wheel'>
          <pose>1.23872 1.28779 0.150002 -1.56825 1.53143 -2.22386</pose>
          <velocity>0.000124 0.000372 -0.001283 0.001845 -0.002623 0.000429</velocity>
          <acceleration>0.163161 0.176801 -1.9989 -0.061008 -0.832457 3.10699</acceleration>
          <wrench>0.163161 0.176801 -1.9989 0 -0 0</wrench>
        </link>
        <link name='right_wheel'>
          <pose>0.874067 1.56819 0.150001 -1.56735 1.54208 -2.22296</pose>
          <velocity>-1.7e-05 0.000262 -0.001471 0.001586 -0.002673 0.000424</velocity>
          <acceleration>0.231885 0.304942 -1.52109 -0.614068 -0.950816 3.13509</acceleration>
          <wrench>0.231885 0.304942 -1.52109 0 -0 0</wrench>
        </link>
        <link name='vertical_link'>
          <pose>1.24995 1.6797 0.431391 -4e-06 -0.060257 -2.22632</pose>
          <velocity>-0.000923 -1.7e-05 -0.000446 0.00155 -0.002985 0.000436</velocity>
          <acceleration>-0.240834 -0.300499 -0.709347 -0.894953 -1.3959 -3.1255</acceleration>
          <wrench>-0.240834 -0.300499 -0.709347 0 -0 0</wrench>
        </link>
      </model>
      <light name='sun'>
        <pose>0 0 10 0 -0 0</pose>
      </light>
    </state>
    <gui fullscreen='0'>
      <camera name='user_camera'>
        <pose>-3.75091 -4.92522 2.35245 -0 0.083644 0.648187</pose>
        <view_controller>orbit</view_controller>
        <projection_type>perspective</projection_type>
      </camera>
    </gui>
  </world>
</sdf>
