<?xml version='1.0'?>
<sdf version='1.5'>
  <model name='me439_robot'>
    <static>false</static>
    <link name='chassis'>
      <pose>0 0 .1 0 0 0</pose>
      <inertial>
        <mass>1.0</mass>
        <inertia> <!-- inertias are tricky to compute -->
          <ixx>0.083</ixx>       <!-- for a box: ixx = 0.083 * mass * (y*y + z*z) -->
          <ixy>0.0</ixy>         <!-- for a box: ixy = 0 -->
          <ixz>0.0</ixz>         <!-- for a box: ixz = 0 -->
          <iyy>0.083</iyy>       <!-- for a box: iyy = 0.083 * mass * (x*x + z*z) -->
          <iyz>0.0</iyz>         <!-- for a box: iyz = 0 -->
          <izz>0.083</izz>       <!-- for a box: izz = 0.083 * mass * (x*x + y*y) -->
        </inertia>
      </inertial>

      <collision name='collision'>
        <geometry>
          <box>
            <size>.8 .4 .1</size>
          </box>
        </geometry>
      </collision>

      <visual name='visual'>
        <geometry>
          <box>
            <size>.8 .4 .1</size>
          </box>
        </geometry>
      </visual>

      <collision name='caster_collision'>
        <pose>-0.3 0 -0.06 0 0 0</pose>
        <geometry>
            <sphere>
            <radius>.06</radius>
          </sphere>
        </geometry>

        <surface>
          <friction>
            <ode>
              <mu>0</mu>
              <mu2>0</mu2>
              <slip1>1.0</slip1>
              <slip2>1.0</slip2>
            </ode>
          </friction>
        </surface>
      </collision>

      <visual name='caster_visual'>
        <pose>-0.3 0 -0.06 0 0 0</pose>
        <geometry>
          <sphere>
            <radius>.06</radius>
          </sphere>
        </geometry>
      </visual>

    </link>

    <link name = "vertical_link">
      <pose relative_to = "chassis" >-0.1 0 0.3 0 0 0</pose>
       <collision name="vertical_collision">
        <inertial>
          <mass>1.0</mass>
          <inertia> <!-- inertias are tricky to compute -->
            <ixx>0.083</ixx>       <!-- for a box: ixx = 0.083 * mass * (y*y + z*z) -->
            <ixy>0.0</ixy>         <!-- for a box: ixy = 0 -->
            <ixz>0.0</ixz>         <!-- for a box: ixz = 0 -->
            <iyy>0.083</iyy>       <!-- for a box: iyy = 0.083 * mass * (x*x + z*z) -->
            <iyz>0.0</iyz>         <!-- for a box: iyz = 0 -->
            <izz>0.083</izz>       <!-- for a box: izz = 0.083 * mass * (x*x + y*y) -->
          </inertia>
        </inertial>
        <geometry>
          <box>
            <size>0.1 0.6 0.60</size>
          </box>
        </geometry>
      </collision>
      <visual name="vertical_visual">
        <geometry>
          <box>
            <size>0.1 0.6 0.60</size>
          </box>
        </geometry>
      </visual>
    </link> 

    <link name="aruco_marker_link">
      <pose relative_to = "vertical_link" >0.051 -0.12 0.0 3.1415 1.5708 0</pose>
      <visual name='visual'>
        <geometry>
          <box>
            <size>0.296 0.296 1e-5</size>
          </box>
        </geometry>
        <material>
          <script>
            <uri>model://moving_platform_with_aruco/materials/scripts</uri>
            <uri>model://moving_platform_with_aruco/materials/textures</uri>
            <name>ArucoVisualMarker1/Marker</name>
          </script>
          <ambient>1 1 1 1</ambient>
          <diffuse>1 1 1 1</diffuse>
          <specular>0 0 0 1</specular>
          <emissive>1 1 1 0</emissive>
          <shader type='vertex'>
            <normal_map>__default__</normal_map>
          </shader>
        </material>
        <cast_shadows>1</cast_shadows>
        <transparency>0</transparency>
      </visual>
    </link>
    <link name="aruco_marker_link_2">
      <pose relative_to = "vertical_link" >0.051 0.11 -0.05 3.1415 1.5708 0 </pose>
      <visual name='visual'>
        <geometry>
          <box>
            <size>0.1355 0.1355 1e-5</size>
          </box>
        </geometry>
        <material>
          <script>
            <uri>model://marker_0/materials/scripts</uri>
            <uri>model://marker_0/materials/textures</uri>
            <name>ArucoVisualMarker0/Marker</name>
          </script>
          <ambient>1 1 1 1</ambient>
          <diffuse>1 1 1 1</diffuse>
          <specular>0 0 0 1</specular>
          <emissive>1 1 1 0</emissive>
          <shader type='vertex'>
            <normal_map>__default__</normal_map>
          </shader>
        </material>
        <cast_shadows>1</cast_shadows>
        <transparency>0</transparency>
      </visual>
    </link>
    <link name="left_wheel">
      <pose>0.2 0.23 0.1 0 1.5707 1.5707</pose>
      <collision name="collision">
        <geometry>
          <cylinder>
            <radius>.15</radius>
            <length>.06</length>
          </cylinder>
        </geometry>
      </collision>
      <visual name="visual">
        <geometry>
          <cylinder>
            <radius>.15</radius>
            <length>.06</length>
          </cylinder>
        </geometry>
      </visual>
    </link>
    
    <link name="right_wheel">
      <pose>0.2 -0.23 0.1 0 1.5707 1.5707</pose>
      <collision name="collision">
        <geometry>
          <cylinder>
            <radius>.15</radius>
            <length>.06</length>
          </cylinder>
        </geometry>
      </collision>
      <visual name="visual">
        <geometry>
          <cylinder>
            <radius>.15</radius>
            <length>.06</length>
          </cylinder>
        </geometry>
      </visual>
    </link>
    <joint name="vertical_platform" type="fixed" >
      <pose>0 0 0 0 0 0</pose>
      <child>vertical_link</child>
      <parent>chassis</parent>
      <axis>
        <xyz>0 0 0</xyz>
      </axis>
    </joint>
    <joint name="aruco_1_fix" type="fixed" >
      <pose>0 0 0 0 0 0</pose>
      <child>aruco_marker_link</child>
      <parent>vertical_link</parent>
      <axis>
        <xyz>0 0 0</xyz>
      </axis>
    </joint>
    <joint name="aruco_2_fix" type="fixed" >
      <pose>0 0 0 0 0 0</pose>
      <child>aruco_marker_link_2</child>
      <parent>vertical_link</parent>
      <axis>
        <xyz>0 0 0</xyz>
      </axis>
    </joint>
    <joint name="left_wheel_hinge" type="revolute" >
      <pose>0 0 0 0 0 0</pose>
      <child>left_wheel</child>
      <parent>chassis</parent>
      <axis>
        <xyz>0 0 1</xyz>
      </axis>
    </joint>

    <joint name="right_wheel_hinge" type="revolute">
      <pose>0 0 0 0 0 0</pose>
      <child>right_wheel</child>
      <parent>chassis</parent>
      <axis>
        <xyz>0 0 1</xyz>
      </axis>
    </joint>
    <plugin filename="libgazebo_ros_diff_drive.so" name="model_diff_drive_plugin">
      <ros>
        <namespace>/platform_robot</namespace>
        <remapping>cmd_vel:=cmd_platform_robot</remapping>
        <remapping>odom:=odom_platform_robot</remapping>
      </ros>

      <!-- kinematics -->
      <wheel_separation>0.46</wheel_separation>
      <wheel_diameter>0.3</wheel_diameter>
      <!-- wheels -->
      <left_joint>left_wheel_hinge</left_joint>
      <right_joint>right_wheel_hinge</right_joint>
      <!-- <left_wheel_hinge>left_wheel_hinge</left_wheel_hinge>
      <right_wheel_hinge>right_wheel_hinge</right_wheel_hinge> -->
      <!-- output -->
      <publish_odom>true</publish_odom>
      <!--<publish_odom_tf>true</publish_odom_tf>
      <publish_wheel_tf>true</publish_wheel_tf> -->

    </plugin>
  </model>
</sdf>
